Workbook

Sheet LEEME
A1: PLANILLA UNIFICADA DE CÁLCULO ESTRUCTURAL – VIVIENDAS Y ESTRUCTURAS SIMPLES
A2: Enfoque Ingeniería · Versión 1.1 · Basada en 'PROYECTO_DE_CALCULO.xlsx' (revisada, corregida y unificada) · CIRSOC 101, 201 e INPRES-CIRSOC 103
B4: Cómo se usa
B5: 1) Cargá los datos comunes en 'Datos' (hormigón, acero, suelo, mampostería).
B6: 2) En 'Cargas' elegí los materiales de cada nivel (listas desplegables) y las sobrecargas.
B7: 3) Cargá y verificá losas, vigas, viguetas/correas y columnas (celdas amarillas).
B8: 4) Definí la acción sísmica en 'Sismo 1', distribuí en planta en 'Sismo 2' y verificá 'Muros'.
B9: 5) Verificá fundaciones. 6) Revisá la hoja 'Resumen': todo debe figurar CUMPLE o '–'.
B10: Los datos cargados son de una vivienda de EJEMPLO: reemplazarlos por los del proyecto. Para agregar más elementos, completar las filas vacías de cada tabla.
B12: Código de colores
B13: Dato de entrada (editable)
B14: Fórmula (no modificar)
B15: Valor traído de otra hoja
B16: CUMPLE
... B20: Hojas del libro
B21: Hoja | C21: Contenido | D21: Norma de referencia
B22: Resumen | C22: Estado de verificaciones y datos clave
B23: Datos | C23: Proyecto, hormigón, acero, suelo, mampostería | D23: CIRSOC 201 · INPRES-CIRSOC 103-III
B24: Cargas | C24: Análisis de cargas y combinaciones | D24: CIRSOC 101 · CIRSOC 201 §9.2
B25: Losas | C25: Losas macizas en una dirección | D25: CIRSOC 201 cap. 7–11
B26: Viguetas y Correas | C26: Viguetas pretensadas y correas de madera | D26: Catálogo · CIRSOC 601
B27: Vigas | C27: Vigas de H°A°: flexión y corte | D27: CIRSOC 201 cap. 9–11
B28: Columnas | C28: Flexocompresión y estribos | D28: CIRSOC 201 cap. 7 y 10
B29: Interaccion | C29: Diagramas P–M (cálculo de apoyo) | D29: CIRSOC 201 §9.3, §10.2
B30: Sismo 1 Accion | C30: Espectro, C, pesos y corte basal | D30: INPRES-CIRSOC 103 Parte I
B31: Sismo 2 Distribucion | C31: Centros de masa y rigidez, torsión y reparto | D31: INPRES-CIRSOC 103 Parte I
B32: Muros | C32: Corte en mampostería y tabiques de H°A° | D32: INPRES-CIRSOC 103 Parte III · CIRSOC 201 §11.10
B33: Voladizos | C33: Columnas en voladizo y componentes no estructurales | D33: INPRES-CIRSOC 103 Parte I
B34: Fundaciones | C34: Cimientos corridos y bases aisladas | D34: CIRSOC 201 cap. 15
B35: Tablas / Tablas Sismo | C35: Datos de consulta | D35: CIRSOC 101 · INPRES-CIRSOC 103
B36: Cambios | C36: Registro de correcciones respecto del original
B38: Versión 1.1 – correcciones respecto de la 1.0
B39: • Losas: se agrega el esquema 'Voladizo' (el ejemplo L3 estaba calculado como simplemente apoyada) y el corte usa el d de la armadura de apoyo.
B40: • Resumen: se eliminan las funciones TEXT() (daban resultados distintos según la configuración regional de Excel).
B41: • Columnas: la búsqueda del punto del diagrama usa SUMPRODUCT en lugar de BUSCAR con orden descendente (más robusto en Excel).
B42: • Viguetas: las series se rotulan 'Serie 3a', etc.; antes la serie '0' se convertía en número al elegirla de la lista y daba error.
B43: • Formato: alturas de fila ajustadas para que no se corten textos; etiquetas de f1 más cortas; filas de Cargas más altas para descripciones largas.
B45: Alcance y limitaciones
B46: • Es una herramienta de apoyo: los resultados deben ser verificados y firmados por el profesional responsable. Los valores de ejemplo (cargas, suelo, secciones) NO son de un proyecto real.
B47: • No incluye: viento (CIRSOC 102), nieve (CIRSOC 104), torsión en vigas, vigas T, losas en dos direcciones, análisis de pórticos, efectos de segundo orden, ni el detallado sismorresistente de CIRSOC 201 cap. 21 e INPRES-CIRSOC 103 Parte II.
...

Sheet Resumen
A1: RESUMEN DE VERIFICACIONES Y RESULTADOS CLAVE
A2: Tablero general: cuenta cuántas verificaciones de cada módulo cumplen, no cumplen o quedan por revisar. Un módulo sin datos cargados figura con '–'.
B4: Verificaciones por módulo
B5: Módulo | C5: Verificaciones | D5: CUMPLE | E5: NO CUMPLE | F5: REVISAR / AUMENTAR | G5: Estado | H5: Ir a la hoja
B6: Losas | C6: =D6+E6+F6 -> 13 | D6: =COUNTIF(Losas!J6:J11,"CUMPLE")+COUNTIF(Losas!J6:J11,"OK")+COUNTIF(Losas!N26:N31,"CUMPLE")+COUNTIF(Losas!N26:N31,"OK")+COUNTIF(Losas!N36:N41,"CUMPLE")+COUNTIF(Losas!N36:N41,"OK")+COUNTIF(Losas!F45:F50,"CUMPLE")+COUNTIF(Losas!F45:F50,"OK")+COUNTIF(Losas!L45:L50,"CUMPLE")+COUNTIF(Losas!L45:L50,"OK") -> 13 | E6: =COUNTIF(Losas!J6:J11,"NO CUMPLE")+COUNTIF(Losas!N26:N31,"NO CUMPLE")+COUNTIF(Losas!N36:N41,"NO CUMPLE")+COUNTIF(Losas!F45:F50,"NO CUMPLE")+COUNTIF(Losas!L45:L50,"NO CUMPLE") -> 0 | F6: =COUNTIF(Losas!J6:J11,"REVISAR*")+COUNTIF(Losas!J6:J11,"AUMENTAR*")+COUNTIF(Losas!N26:N31,"REVISAR*")+COUNTIF(Losas!N26:N31,"AUMENTAR*")+COUNTIF(Losas!N36:N41,"REVISAR*")+COUNTIF(Losas!N36:N41,"AUMENTAR*")+COUNTIF(Losas!F45:F50,"REVISAR*")+COUNTIF(Losas!F45:F50,"AUMENTAR*")+COUNTIF(Losas!L45:L50,"REVISAR*")+COUNTIF(Losas!L45:L50,"AUMENTAR*") -> 0 | G6: =IF(E6>0,"NO CUMPLE",IF(F6>0,"REVISAR",IF(D6>0,"CUMPLE","–"))) -> CUMPLE | H6: Losas
B7: Vigas | C7: =D7+E7+F7 -> 7 | D7: =COUNTIF(Vigas!I6:I11,"CUMPLE")+COUNTIF(Vigas!I6:I11,"OK")+COUNTIF(Vigas!P25:P36,"CUMPLE")+COUNTIF(Vigas!P25:P36,"OK")+COUNTIF(Vigas!N41:N46,"CUMPLE")+COUNTIF(Vigas!N41:N46,"OK") -> 7 | E7: =COUNTIF(Vigas!I6:I11,"NO CUMPLE")+COUNTIF(Vigas!P25:P36,"NO CUMPLE")+COUNTIF(Vigas!N41:N46,"NO CUMPLE") -> 0 | F7: =COUNTIF(Vigas!I6:I11,"REVISAR*")+COUNTIF(Vigas!I6:I11,"AUMENTAR*")+COUNTIF(Vigas!P25:P36,"REVISAR*")+COUNTIF(Vigas!P25:P36,"AUMENTAR*")+COUNTIF(Vigas!N41:N46,"REVISAR*")+COUNTIF(Vigas!N41:N46,"AUMENTAR*") -> 0 | G7: =IF(E7>0,"NO CUMPLE",IF(F7>0,"REVISAR",IF(D7>0,"CUMPLE","–"))) -> CUMPLE | H7: Vigas
B8: Viguetas pretensadas y correas de madera | C8: =D8+E8+F8 -> 3 | D8: =COUNTIF('Viguetas y Correas'!M7:M10,"CUMPLE")+COUNTIF('Viguetas y Correas'!M7:M10,"OK")+COUNTIF('Viguetas y Correas'!R15:R18,"CUMPLE")+COUNTIF('Viguetas y Correas'!R15:R18,"OK") -> 3 | E8: =COUNTIF('Viguetas y Correas'!M7:M10,"NO CUMPLE")+COUNTIF('Viguetas y Correas'!R15:R18,"NO CUMPLE") -> 0 | F8: =COUNTIF('Viguetas y Correas'!M7:M10,"REVISAR*")+COUNTIF('Viguetas y Correas'!M7:M10,"AUMENTAR*")+COUNTIF('Viguetas y Correas'!R15:R18,"REVISAR*")+COUNTIF('Viguetas y Correas'!R15:R18,"AUMENTAR*") -> 0 | G8: =IF(E8>0,"NO CUMPLE",IF(F8>0,"REVISAR",IF(D8>0,"CUMPLE","–"))) -> CUMPLE | H8: Viguetas y Correas
B9: Columnas | C9: =D9+E9+F9 -> 12 | D9: =COUNTIF(Columnas!O16:O21,"CUMPLE")+COUNTIF(Columnas!O16:O21,"OK")+COUNTIF(Columnas!P16:P21,"CUMPLE")+COUNTIF(Columnas!P16:P21,"OK")+COUNTIF(Columnas!Q16:Q21,"CUMPLE")+COUNTIF(Columnas!Q16:Q21,"OK")+COUNTIF(Columnas!S16:S21,"CUMPLE")+COUNTIF(Columnas!S16:S21,"OK") -> 12 | E9: =COUNTIF(Columnas!O16:O21,"NO CUMPLE")+COUNTIF(Columnas!P16:P21,"NO CUMPLE")+COUNTIF(Columnas!Q16:Q21,"NO CUMPLE")+COUNTIF(Columnas!S16:S21,"NO CUMPLE") -> 0 | F9: =COUNTIF(Columnas!O16:O21,"REVISAR*")+COUNTIF(Columnas!O16:O21,"AUMENTAR*")+COUNTIF(Columnas!P16:P21,"REVISAR*")+COUNTIF(Columnas!P16:P21,"AUMENTAR*")+COUNTIF(Columnas!Q16:Q21,"REVISAR*")+COUNTIF(Columnas!Q16:Q21,"AUMENTAR*")+COUNTIF(Columnas!S16:S21,"REVISAR*")+COUNTIF(Columnas!S16:S21,"AUMENTAR*") -> 0 | G9: =IF(E9>0,"NO CUMPLE",IF(F9>0,"REVISAR",IF(D9>0,"CUMPLE","–"))) -> CUMPLE | H9: Columnas
B10: Muros (mampostería y tabiques) | C10: =D10+E10+F10 -> 6 | D10: =COUNTIF(Muros!N6:N19,"CUMPLE")+COUNTIF(Muros!N6:N19,"OK")+COUNTIF(Muros!P24:Q29,"CUMPLE")+COUNTIF(Muros!P24:Q29,"OK") -> 6 | E10: =COUNTIF(Muros!N6:N19,"NO CUMPLE")+COUNTIF(Muros!P24:Q29,"NO CUMPLE") -> 0 | F10: =COUNTIF(Muros!N6:N19,"REVISAR*")+COUNTIF(Muros!N6:N19,"AUMENTAR*")+COUNTIF(Muros!P24:Q29,"REVISAR*")+COUNTIF(Muros!P24:Q29,"AUMENTAR*") -> 0 | G10: =IF(E10>0,"NO CUMPLE",IF(F10>0,"REVISAR",IF(D10>0,"CUMPLE","–"))) -> CUMPLE | H10: Muros
B11: Fundaciones | C11: =D11+E11+F11 -> 10 | D11: =COUNTIF(Fundaciones!O6:O11,"CUMPLE")+COUNTIF(Fundaciones!O6:O11,"OK")+COUNTIF(Fundaciones!N16:N19,"CUMPLE")+COUNTIF(Fundaciones!N16:N19,"OK")+COUNTIF(Fundaciones!N24:N27,"CUMPLE")+COUNTIF(Fundaciones!N24:N27,"OK")+COUNTIF(Fundaciones!E32:E35,"CUMPLE")+COUNTIF(Fundaciones!E32:E35,"OK")+COUNTIF(Fundaciones!I32:I35,"CUMPLE")+COUNTIF(Fundaciones!I32:I35,"OK") -> 10 | E11: =COUNTIF(Fundaciones!O6:O11,"NO CUMPLE")+COUNTIF(Fundaciones!N16:N19,"NO CUMPLE")+COUNTIF(Fundaciones!N24:N27,"NO CUMPLE")+COUNTIF(Fundaciones!E32:E35,"NO CUMPLE")+COUNTIF(Fundaciones!I32:I35,"NO CUMPLE") -> 0 | F11: =COUNTIF(Fundaciones!O6:O11,"REVISAR*")+COUNTIF(Fundaciones!O6:O11,"AUMENTAR*")+COUNTIF(Fundaciones!N16:N19,"REVISAR*")+COUNTIF(Fundaciones!N16:N19,"AUMENTAR*")+COUNTIF(Fundaciones!N24:N27,"REVISAR*")+COUNTIF(Fundaciones!N24:N27,"AUMENTAR*")+COUNTIF(Fundaciones!E32:E35,"REVISAR*")+COUNTIF(Fundaciones!E32:E35,"AUMENTAR*")+COUNTIF(Fundaciones!I32:I35,"REVISAR*")+COUNTIF(Fundaciones!I32:I35,"AUMENTAR*") -> 0 | G11: =IF(E11>0,"NO CUMPLE",IF(F11>0,"REVISAR",IF(D11>0,"CUMPLE","–"))) -> CUMPLE | H11: Fundaciones
B12: Columnas en voladizo | C12: =D12+E12+F12 -> 1 | D12: =COUNTIF(Voladizos!P7:P10,"CUMPLE")+COUNTIF(Voladizos!P7:P10,"OK") -> 1 | E12: =COUNTIF(Voladizos!P7:P10,"NO CUMPLE") -> 0 | F12: =COUNTIF(Voladizos!P7:P10,"REVISAR*")+COUNTIF(Voladizos!P7:P10,"AUMENTAR*") -> 0 | G12: =IF(E12>0,"NO CUMPLE",IF(F12>0,"REVISAR",IF(D12>0,"CUMPLE","–"))) -> CUMPLE | H12: Voladizos
B13: Distribución sísmica (equilibrio) | C13: =D13+E13+F13 -> 2 | D13: =COUNTIF('Sismo 2 Distribucion'!I72:I73,"CUMPLE")+COUNTIF('Sismo 2 Distribucion'!I72:I73,"OK") -> 2 | E13: =COUNTIF('Sismo 2 Distribucion'!I72:I73,"NO CUMPLE") -> 0 | F13: =COUNTIF('Sismo 2 Distribucion'!I72:I73,"REVISAR*")+COUNTIF('Sismo 2 Distribucion'!I72:I73,"AUMENTAR*") -> 0 | G13: =IF(E13>0,"NO CUMPLE",IF(F13>0,"REVISAR",IF(D13>0,"CUMPLE","–"))) -> CUMPLE | H13: Sismo 2 Distribucion
B14: TOTAL | C14: =SUM(C6:C13) -> 54 | D14: =SUM(D6:D13) -> 54 | E14: =SUM(E6:E13) -> 0 | F14: =SUM(F6:F13) -> 0 | G14: =IF(E14>0,"NO CUMPLE",IF(F14>0,"REVISAR","CUMPLE")) -> CUMPLE
B17: Datos y resultados clave
B18: Hormigón / acero | C18: =Datos!C13&" · f'c = "&ROUND(Datos!$C$14,0)&" MPa | "&Datos!C24&" · fy = "&ROUND(Datos!$C$25,0)&" MPa" -> H-25 · f'c = 25 MPa | ADN 420 · fy = 420 MPa
B19: Tensión admisible del suelo | C19: =ROUND(Datos!$C$31,0)&" kPa ("&ROUND(Datos!C32,2)&" kgf/cm²)" -> 150 kPa (1.53 kgf/cm²)
B20: Carga permanente D techo / entrepiso (sin losa) | C20: =ROUND(Cargas!$I$16,2)&" / "&ROUND(Cargas!$I$28,2)&" kN/m²" -> 2.14 / 2.32 kN/m²
B21: Carga mayorada qu techo / entrepiso (con losa estimada) | C21: =ROUND(Cargas!$I$45,2)&" / "&ROUND(Cargas!$J$45,2)&" kN/m²" -> 7.77 / 9.58 kN/m²
B22: Zona sísmica · tipo de suelo · grupo | C22: ="Zona "&'Sismo 1 Accion'!$C$5&" · Tipo "&'Sismo 1 Accion'!$C$6&" · "&'Sismo 1 Accion'!$C$9 -> Zona 4 · Tipo 2 · Grupo B
B23: Coeficiente sísmico C (R = ...) | C23: =ROUND('Sismo 1 Accion'!$C$37,3)&" (R = "&ROUND('Sismo 1 Accion'!$C$14,1)&")" -> 0.333 (R = 3)
B24: Peso sísmico W / Corte basal V0 | C24: =ROUND('Sismo 1 Accion'!$C$64,1)&" kN / "&ROUND('Sismo 1 Accion'!$C$65,1)&" kN" -> 732.9 kN / 244.3 kN
B26: Estado 'CUMPLE' significa que las verificaciones implementadas se satisfacen con los datos cargados; no reemplaza la revisión del profesional responsable ni verificaciones no incluidas (viento, nieve, torsión en vigas, estabilidad global, detalles sismorresistentes, etc.).

Sheet Datos
A1: DATOS GENERALES · MATERIALES · SUELO
A2: Única hoja donde se cargan los datos comunes. Todas las demás hojas leen estos valores (celdas amarillas = datos de entrada; el resto se calcula solo).
B4: 1. Proyecto
B5: Obra | C5: Vivienda unifamiliar – EJEMPLO (reemplazar)
B6: Ubicación | C6: Mendoza – Capital
B7: Comitente
B8: Proyectista / Responsable
B9: Fecha | C9: 10/10/2026
B10: Revisión | C10: 00
B12: 2. Hormigón (CIRSOC 201-2005)
B13: Clase de hormigón | C13: H-25 | E13: Lista desplegable. Mínimo habitual H-20; INPRES-CIRSOC 103 P.III 4.2.1 exige f'c ≥ 20 MPa en encadenados.
B14: Resistencia especificada f'c | C14: =INDEX(Tablas!$L$19:$L$24,MATCH(C13,Tablas!$K$19:$K$24,0)) -> 25 | D14: MPa
B15: Módulo de elasticidad Ec = 4700·√f'c | C15: =4700*SQRT(C14) -> 23500 | D15: MPa | E15: CIRSOC 201 §8.5.1
B16: Factor β1 | C16: =IF(C14<=30,0.85,MAX(0.65,0.85-0.05*(C14-30)/7)) -> 0.85 | D16: – | E16: CIRSOC 201 §10.2.7.3
B17: Peso unitario H°A° | C17: 25 | D17: kN/m³ | E17: CIRSOC 101 Tabla 3.1 (hormigón armado = 25 kN/m³). Se usa en TODAS las hojas.
B18: Peso unitario H° simple / ciclópeo | C18: 22 | D18: kN/m³ | E18: Cimientos de hormigón ciclópeo (la planilla original usaba 2200 kg/m³).
B19: Recubrimiento libre – vigas y columnas | C19: 40 | D19: mm | E19: CIRSOC 201 §7.7 (interior 40 mm; ambientes agresivos o a la intemperie: aumentar).
B20: Recubrimiento libre – losas | C20: 20 | D20: mm | E20: CIRSOC 201 §7.7 (losas y tabiques interiores 20 mm).
B21: Recubrimiento libre – fundaciones (contra el suelo) | C21: 70 | D21: mm | E21: CIRSOC 201 §7.7 (hormigón en contacto permanente con el suelo: 70 mm).
B23: 3. Acero (CIRSOC 201-2005)
B24: Acero longitudinal | C24: ADN 420 | E24: Lista desplegable.
B25: Tensión de fluencia fy | C25: =INDEX(Tablas!$L$27:$L$29,MATCH(C24,Tablas!$K$27:$K$29,0)) -> 420 | D25: MPa
B26: Acero de estribos | C26: ADN 420 | E26: Lista desplegable.
B27: Tensión de fluencia de estribos fyt | C27: =INDEX(Tablas!$L$27:$L$29,MATCH(C26,Tablas!$K$27:$K$29,0)) -> 420 | D27: MPa
B28: Módulo de elasticidad del acero Es | C28: 200000 | D28: MPa | E28: CIRSOC 201 §8.5.2
B30: 4. Suelo y fundaciones
B31: Tensión admisible del suelo σadm | C31: 150 | D31: kPa | E31: DATO DEL ESTUDIO DE SUELOS. (150 kPa ≈ 1,5 kgf/cm²; es un valor de EJEMPLO.)
B32: σadm equivalente | C32: =C31/98.0665 -> 1.5295743 | D32: kgf/cm²
B33: Profundidad de fundación Df | C33: 1 | D33: m | E33: Desde el nivel del terreno a la base de la fundación.
B34: Peso unitario del suelo γs | C34: 17 | D34: kN/m³ | E34: CIRSOC 101 Tabla 3.1 (suelo no sumergido) o del estudio de suelos.
B35: Peso unitario de mampostería con revoque | C35: 17 | D35: kN/m³ | E35: CIRSOC 101 Tabla 3.1 (ladrillo macizo común con revoque = 17 kN/m³).
B37: 5. Mampostería (INPRES-CIRSOC 103 Parte III – 2018)
B38: Tipo de mampuesto | C38: Ladrillos cerámicos macizos | E38: Lista desplegable.
B39: Tipo de mortero de asiento | C39: N | E39: E = elevada · I = intermedia · N = normal · NA = cemento de albañilería (Tabla 2.1).
B40: Resistencia a compresión f'm | C40: =INDEX(Tablas!$L$50:$O$52,MATCH(C38,Tablas!$K$50:$K$52,0),MATCH(C39,Tablas!$L$48:$O$48,0)) -> 1.75 | D40: MPa | E40: Tabla 2.4 (valores indicativos)
B41: Resistencia al corte f'v | C41: =INDEX(Tablas!$L$55:$O$57,MATCH(C38,Tablas!$K$50:$K$52,0),MATCH(C39,Tablas!$L$48:$O$48,0)) -> 0.19 | D41: MPa | E41: Tabla 2.5 (valores indicativos)
B42: Módulo de elasticidad Em = 1200·f'm | C42: =1200*C40 -> 2100 | D42: MPa | E42: Art. 2.4.1
B43: Módulo de corte Gm | C43: =IF(C38="Ladrillos cerámicos macizos",0.2,0.1)*C42 -> 420 | D43: MPa | E43: Art. 2.4.2: 0,20·Em (ladrillo macizo) · 0,10·Em (bloques huecos). La planilla original usaba 0,4·E (error).
B45: Leyenda de colores: celda amarilla con letra azul = dato que se carga · celda blanca = fórmula (no tocar) · letra verde = valor traído de otra hoja.

Sheet Cargas
A1: ANÁLISIS DE CARGAS Y COMBINACIONES (CIRSOC 101-2005 y CIRSOC 201-2005 §9.2)
A2: Se cargan las capas de cada nivel eligiendo el material de la lista (CIRSOC 101 Tabla 3.1). El peso propio de la estructura (losa) se agrega en la hoja Losas.
B4: CARGA PERMANENTE D – TECHO / CUBIERTA (sin peso propio de la losa)
B5: Material (elegir de la lista) | C5: γ [kN/m³] | D5: q [kN/m²] | E5: e / h [m] | F5: b [m] | G5: sep [m] | H5: α [°] | I5: q calculado [kN/m²] | J5: Observación
B6: Cubierta impermeabilizante con base de tela o cartón asfáltico de siete capas | C6: =IF($B6="",0,N(INDEX(Tablas!$D$5:$D$300,MATCH($B6,Tablas!$B$5:$B$300,0)))) -> 0 | D6: =IF($B6="",0,N(INDEX(Tablas!$C$5:$C$300,MATCH($B6,Tablas!$B$5:$B$300,0)))) -> 0.1 | H6: 0 | I6: =IF($B6="",0,IF(D6>0,D6,IF(C6>0,IF(AND(G6>0,F6>0),C6*E6*F6/G6,C6*E6),0))/COS(RADIANS(H6))) -> 0.1 | J6: =IF(AND($B6<>"",I6=0),"Completar e [m]","")
B7: Contrapiso de cemento, arena y cascote | C7: =IF($B7="",0,N(INDEX(Tablas!$D$5:$D$300,MATCH($B7,Tablas!$B$5:$B$300,0)))) -> 18 | D7: =IF($B7="",0,N(INDEX(Tablas!$C$5:$C$300,MATCH($B7,Tablas!$B$5:$B$300,0)))) -> 0 | E7: 0.08 | H7: 0 | I7: =IF($B7="",0,IF(D7>0,D7,IF(C7>0,IF(AND(G7>0,F7>0),C7*E7*F7/G7,C7*E7),0))/COS(RADIANS(H7))) -> 1.44 | J7: =IF(AND($B7<>"",I7=0),"Completar e [m]","")
B8: Mortero de cemento pórtland y arena | C8: =IF($B8="",0,N(INDEX(Tablas!$D$5:$D$300,MATCH($B8,Tablas!$B$5:$B$300,0)))) -> 21 | D8: =IF($B8="",0,N(INDEX(Tablas!$C$5:$C$300,MATCH($B8,Tablas!$B$5:$B$300,0)))) -> 0 | E8: 0.02 | H8: 0 | I8: =IF($B8="",0,IF(D8>0,D8,IF(C8>0,IF(AND(G8>0,F8>0),C8*E8*F8/G8,C8*E8),0))/COS(RADIANS(H8))) -> 0.42 | J8: =IF(AND($B8<>"",I8=0),"Completar e [m]","")
B9: Yeso con metal desplegado | C9: =IF($B9="",0,N(INDEX(Tablas!$D$5:$D$300,MATCH($B9,Tablas!$B$5:$B$300,0)))) -> 0 | D9: =IF($B9="",0,N(INDEX(Tablas!$C$5:$C$300,MATCH($B9,Tablas!$B$5:$B$300,0)))) -> 0.18 | H9: 0 | I9: =IF($B9="",0,IF(D9>0,D9,IF(C9>0,IF(AND(G9>0,F9>0),C9*E9*F9/G9,C9*E9),0))/COS(RADIANS(H9))) -> 0.18 | J9: =IF(AND($B9<>"",I9=0),"Completar e [m]","")
C10: =IF($B10="",0,N(INDEX(Tablas!$D$5:$D$300,MATCH($B10,Tablas!$B$5:$B$300,0)))) -> 0 | D10: =IF($B10="",0,N(INDEX(Tablas!$C$5:$C$300,MATCH($B10,Tablas!$B$5:$B$300,0)))) -> 0 | I10: =IF($B10="",0,IF(D10>0,D10,IF(C10>0,IF(AND(G10>0,F10>0),C10*E10*F10/G10,C10*E10),0))/COS(RADIANS(H10))) -> 0 | J10: =IF(AND($B10<>"",I10=0),"Completar e [m]","")
C11: =IF($B11="",0,N(INDEX(Tablas!$D$5:$D$300,MATCH($B11,Tablas!$B$5:$B$300,0)))) -> 0 | D11: =IF($B11="",0,N(INDEX(Tablas!$C$5:$C$300,MATCH($B11,Tablas!$B$5:$B$300,0)))) -> 0 | I11: =IF($B11="",0,IF(D11>0,D11,IF(C11>0,IF(AND(G11>0,F11>0),C11*E11*F11/G11,C11*E11),0))/COS(RADIANS(H11))) -> 0 | J11: =IF(AND($B11<>"",I11=0),"Completar e [m]","")
C12: =IF($B12="",0,N(INDEX(Tablas!$D$5:$D$300,MATCH($B12,Tablas!$B$5:$B$300,0)))) -> 0 | D12: =IF($B12="",0,N(INDEX(Tablas!$C$5:$C$300,MATCH($B12,Tablas!$B$5:$B$300,0)))) -> 0 | I12: =IF($B12="",0,IF(D12>0,D12,IF(C12>0,IF(AND(G12>0,F12>0),C12*E12*F12/G12,C12*E12),0))/COS(RADIANS(H12))) -> 0 | J12: =IF(AND($B12<>"",I12=0),"Completar e [m]","")
C13: =IF($B13="",0,N(INDEX(Tablas!$D$5:$D$300,MATCH($B13,Tablas!$B$5:$B$300,0)))) -> 0 | D13: =IF($B13="",0,N(INDEX(Tablas!$C$5:$C$300,MATCH($B13,Tablas!$B$5:$B$300,0)))) -> 0 | I13: =IF($B13="",0,IF(D13>0,D13,IF(C13>0,IF(AND(G13>0,F13>0),C13*E13*F13/G13,C13*E13),0))/COS(RADIANS(H13))) -> 0 | J13: =IF(AND($B13<>"",I13=0),"Completar e [m]","")
B14: Estructura de cubierta liviana (correas / perfil de chapa plegada) – opcional
C15: =IF($B15="",0,N(INDEX(Tablas!$W$5:$W$553,MATCH($B15,Tablas!$V$5:$V$553,0)))) -> 0 | D15: kN/m | H15: 0 | I15: =IF(OR($B15="",G15=0),0,C15/G15/COS(RADIANS(H15))) -> 0 | J15: q = peso/sep (sep entre correas)
B16: D TECHO / CUBIERTA (sin peso propio de losa) | I16: =SUM(I6:I13)+I15 -> 2.14 | J16: kN/m²
B18: CARGA PERMANENTE D – ENTREPISO (sin peso propio de la losa)
B19: Material (elegir de la lista) | C19: γ [kN/m³] | D19: q [kN/m²] | E19: e / h [m] | F19: b [m] | G19: sep [m] | H19: α [°] | I19: q calculado [kN/m²] | J19: Observación
B20: Baldosa cerámica, 12 mm de espesor | C20: =IF($B20="",0,N(INDEX(Tablas!$D$5:$D$300,MATCH($B20,Tablas!$B$5:$B$300,0)))) -> 23 | D20: =IF($B20="",0,N(INDEX(Tablas!$C$5:$C$300,MATCH($B20,Tablas!$B$5:$B$300,0)))) -> 0.28 | H20: 0 | I20: =IF($B20="",0,IF(D20>0,D20,IF(C20>0,IF(AND(G20>0,F20>0),C20*E20*F20/G20,C20*E20),0))/COS(RADIANS(H20))) -> 0.28 | J20: =IF(AND($B20<>"",I20=0),"Completar e [m]","")
B21: Contrapiso de cemento, arena y cascote | C21: =IF($B21="",0,N(INDEX(Tablas!$D$5:$D$300,MATCH($B21,Tablas!$B$5:$B$300,0)))) -> 18 | D21: =IF($B21="",0,N(INDEX(Tablas!$C$5:$C$300,MATCH($B21,Tablas!$B$5:$B$300,0)))) -> 0 | E21: 0.08 | H21: 0 | I21: =IF($B21="",0,IF(D21>0,D21,IF(C21>0,IF(AND(G21>0,F21>0),C21*E21*F21/G21,C21*E21),0))/COS(RADIANS(H21))) -> 1.44 | J21: =IF(AND($B21<>"",I21=0),"Completar e [m]","")
B22: Mortero de cemento pórtland y arena | C22: =IF($B22="",0,N(INDEX(Tablas!$D$5:$D$300,MATCH($B22,Tablas!$B$5:$B$300,0)))) -> 21 | D22: =IF($B22="",0,N(INDEX(Tablas!$C$5:$C$300,MATCH($B22,Tablas!$B$5:$B$300,0)))) -> 0 | E22: 0.02 | H22: 0 | I22: =IF($B22="",0,IF(D22>0,D22,IF(C22>0,IF(AND(G22>0,F22>0),C22*E22*F22/G22,C22*E22),0))/COS(RADIANS(H22))) -> 0.42 | J22: =IF(AND($B22<>"",I22=0),"Completar e [m]","")
B23: Yeso con metal desplegado | C23: =IF($B23="",0,N(INDEX(Tablas!$D$5:$D$300,MATCH($B23,Tablas!$B$5:$B$300,0)))) -> 0 | D23: =IF($B23="",0,N(INDEX(Tablas!$C$5:$C$300,MATCH($B23,Tablas!$B$5:$B$300,0)))) -> 0.18 | H23: 0 | I23: =IF($B23="",0,IF(D23>0,D23,IF(C23>0,IF(AND(G23>0,F23>0),C23*E23*F23/G23,C23*E23),0))/COS(RADIANS(H23))) -> 0.18 | J23: =IF(AND($B23<>"",I23=0),"Completar e [m]","")
C24: =IF($B24="",0,N(INDEX(Tablas!$D$5:$D$300,MATCH($B24,Tablas!$B$5:$B$300,0)))) -> 0 | D24: =IF($B24="",0,N(INDEX(Tablas!$C$5:$C$300,MATCH($B24,Tablas!$B$5:$B$300,0)))) -> 0 | I24: =IF($B24="",0,IF(D24>0,D24,IF(C24>0,IF(AND(G24>0,F24>0),C24*E24*F24/G24,C24*E24),0))/COS(RADIANS(H24))) -> 0 | J24: =IF(AND($B24<>"",I24=0),"Completar e [m]","")
C25: =IF($B25="",0,N(INDEX(Tablas!$D$5:$D$300,MATCH($B25,Tablas!$B$5:$B$300,0)))) -> 0 | D25: =IF($B25="",0,N(INDEX(Tablas!$C$5:$C$300,MATCH($B25,Tablas!$B$5:$B$300,0)))) -> 0 | I25: =IF($B25="",0,IF(D25>0,D25,IF(C25>0,IF(AND(G25>0,F25>0),C25*E25*F25/G25,C25*E25),0))/COS(RADIANS(H25))) -> 0 | J25: =IF(AND($B25<>"",I25=0),"Completar e [m]","")
C26: =IF($B26="",0,N(INDEX(Tablas!$D$5:$D$300,MATCH($B26,Tablas!$B$5:$B$300,0)))) -> 0 | D26: =IF($B26="",0,N(INDEX(Tablas!$C$5:$C$300,MATCH($B26,Tablas!$B$5:$B$300,0)))) -> 0 | I26: =IF($B26="",0,IF(D26>0,D26,IF(C26>0,IF(AND(G26>0,F26>0),C26*E26*F26/G26,C26*E26),0))/COS(RADIANS(H26))) -> 0 | J26: =IF(AND($B26<>"",I26=0),"Completar e [m]","")
C27: =IF($B27="",0,N(INDEX(Tablas!$D$5:$D$300,MATCH($B27,Tablas!$B$5:$B$300,0)))) -> 0 | D27: =IF($B27="",0,N(INDEX(Tablas!$C$5:$C$300,MATCH($B27,Tablas!$B$5:$B$300,0)))) -> 0 | I27: =IF($B27="",0,IF(D27>0,D27,IF(C27>0,IF(AND(G27>0,F27>0),C27*E27*F27/G27,C27*E27),0))/COS(RADIANS(H27))) -> 0 | J27: =IF(AND($B27<>"",I27=0),"Completar e [m]","")
B28: D ENTREPISO (sin peso propio de losa) | I28: =SUM(I20:I27) -> 2.32 | J28: kN/m²
B30: SOBRECARGAS (CIRSOC 101 Tabla 4.1)
B31: Destino (elegir de la lista) | D31: L [kN/m²] | I31: Valor adoptado | J31: Uso
B32: Azoteas y terrazas inaccesibles | D32: =IF($B32="",0,N(INDEX(Tablas!$H$5:$H$77,MATCH($B32,Tablas!$G$5:$G$77,0)))) -> 1 | I32: =D32 -> 1 | J32: Lr (techo)
B33: Usos Residenciales (casa habitación, departamentos): viviendas para 1 y 2 familias - todas las áreas excepto balcones | D33: =IF($B33="",0,N(INDEX(Tablas!$H$5:$H$77,MATCH($B33,Tablas!$G$5:$G$77,0)))) -> 2 | I33: =D33 -> 2 | J33: L (entrepiso)
B34: Sobrecarga de uso sobre el techo (terraza usable como piso) – 0 si no corresponde | I34: 0 | J34: L (techo)
B35: Sobrecarga de techo sobre el entrepiso – 0 si no corresponde | I35: 0 | J35: Lr (entrepiso)
B36: Factor de L en las combinaciones (0,5 salvo cocheras, locales de reunión pública o L > 4,8 kN/m² → 1,0) | I36: 0.5 | J36: CIRSOC 201 §9.2.1
B38: COMBINACIONES DE CARGA (CIRSOC 201-2005 §9.2) – sin viento ni sismo
B39: Peso propio estimado de la losa para esta verificación orientativa: espesor h [m] | I39: 0.12 | J39: (la hoja Losas usa el h real)
B40: Combinación | I40: TECHO [kN/m²] | J40: ENTREPISO [kN/m²]
B41: D' = D + γH°A°·h_est (carga permanente total) | I41: =Cargas!$I$16+Datos!$C$17*Cargas!$I$39 -> 5.14 | J41: =Cargas!$I$28+Datos!$C$17*Cargas!$I$39 -> 5.32
B42: U1 = 1,4·D' | I42: =1.4*(I41) -> 7.196 | J42: =1.4*(J41) -> 7.448
B43: U2 = 1,2·D' + 1,6·L + 0,5·Lr | I43: =1.2*(I41)+1.6*Cargas!$I$34+0.5*Cargas!$I$32 -> 6.668 | J43: =1.2*(J41)+1.6*Cargas!$I$33+0.5*Cargas!$I$35 -> 9.584
B44: U3 = 1,2·D' + 1,6·Lr + fL·L | I44: =1.2*(I41)+1.6*Cargas!$I$32+Cargas!$I$36*Cargas!$I$34 -> 7.768 | J44: =1.2*(J41)+1.6*Cargas!$I$35+Cargas!$I$36*Cargas!$I$33 -> 7.384
...

Sheet Losas
A1: LOSAS MACIZAS ARMADAS EN UNA DIRECCIÓN (CIRSOC 201-2005)
A2: Franja de 1 m de ancho. Se cargan los datos en las celdas amarillas; la hoja predimensiona, calcula esfuerzos y verifica la armadura. Los resultados 'CUMPLE / NO CUMPLE' indican si la verificación se satisface.
B4: 1. Predimensionado de espesor – CIRSOC 201 Tabla 9.5(a)
B5: Losa | C5: Tipo de elemento | D5: Condición de apoyo | E5: Luz L [m] | F5: Divisor (L/x) | G5: Factor fy | H5: h mín [cm] | I5: h adoptado [cm] | J5: Verificación
B6: L1 | C6: Losa maciza en una dirección | D6: Simplemente apoyado | E6: 3 | F6: =IF($B6="","",INDEX(Tablas!$L$43:$O$44,MATCH(C6,Tablas!$K$43:$K$44,0),MATCH(D6,Tablas!$L$42:$O$42,0))) -> 20 | G6: =IF($B6="","",IF(Datos!$C$25=420,1,0.4+Datos!$C$25/700)) -> 1 | H6: =IF($B6="","",E6/F6*G6*100) -> 15 | I6: 15 | J6: =IF($B6="","",IF(I6>=H6,"CUMPLE","NO CUMPLE")) -> CUMPLE
B7: L2 | C7: Losa maciza en una dirección | D7: Un extremo continuo | E7: 3.2 | F7: =IF($B7="","",INDEX(Tablas!$L$43:$O$44,MATCH(C7,Tablas!$K$43:$K$44,0),MATCH(D7,Tablas!$L$42:$O$42,0))) -> 24 | G7: =IF($B7="","",IF(Datos!$C$25=420,1,0.4+Datos!$C$25/700)) -> 1 | H7: =IF($B7="","",E7/F7*G7*100) -> 13.333333 | I7: 14 | J7: =IF($B7="","",IF(I7>=H7,"CUMPLE","NO CUMPLE")) -> CUMPLE
B8: L3 | C8: Losa maciza en una dirección | D8: Voladizo | E8: 1.2 | F8: =IF($B8="","",INDEX(Tablas!$L$43:$O$44,MATCH(C8,Tablas!$K$43:$K$44,0),MATCH(D8,Tablas!$L$42:$O$42,0))) -> 10 | G8: =IF($B8="","",IF(Datos!$C$25=420,1,0.4+Datos!$C$25/700)) -> 1 | H8: =IF($B8="","",E8/F8*G8*100) -> 12 | I8: 12 | J8: =IF($B8="","",IF(I8>=H8,"CUMPLE","NO CUMPLE")) -> CUMPLE
F9: =IF($B9="","",INDEX(Tablas!$L$43:$O$44,MATCH(C9,Tablas!$K$43:$K$44,0),MATCH(D9,Tablas!$L$42:$O$42,0))) | G9: =IF($B9="","",IF(Datos!$C$25=420,1,0.4+Datos!$C$25/700)) | H9: =IF($B9="","",E9/F9*G9*100) | J9: =IF($B9="","",IF(I9>=H9,"CUMPLE","NO CUMPLE"))
F10: =IF($B10="","",INDEX(Tablas!$L$43:$O$44,MATCH(C10,Tablas!$K$43:$K$44,0),MATCH(D10,Tablas!$L$42:$O$42,0))) | G10: =IF($B10="","",IF(Datos!$C$25=420,1,0.4+Datos!$C$25/700)) | H10: =IF($B10="","",E10/F10*G10*100) | J10: =IF($B10="","",IF(I10>=H10,"CUMPLE","NO CUMPLE"))
F11: =IF($B11="","",INDEX(Tablas!$L$43:$O$44,MATCH(C11,Tablas!$K$43:$K$44,0),MATCH(D11,Tablas!$L$42:$O$42,0))) | G11: =IF($B11="","",IF(Datos!$C$25=420,1,0.4+Datos!$C$25/700)) | H11: =IF($B11="","",E11/F11*G11*100) | J11: =IF($B11="","",IF(I11>=H11,"CUMPLE","NO CUMPLE"))
B12: El factor fy corrige los divisores para aceros distintos de 420 MPa: (0,4 + fy/700). Se verifica deformación solo por altura mínima; si h < h mín hay que calcular flechas (CIRSOC 201 §9.5).
B14: 2. Cargas y esfuerzos (franja de 1 m)
B15: Losa | C15: Nivel | D15: Esquema estático | E15: L [m] | F15: h [cm] | G15: D' [kN/m²] | H15: L [kN/m²] | I15: Lr [kN/m²] | J15: qu [kN/m²] | K15: Mu(+) [kNm/m] | L15: Mu(−) apoyo [kNm/m] | M15: Vu [kN/m] | N15: Reacción apoyo ext. [kN/m] | O15: Reacción apoyo central [kN/m]
B16: =IF(B6="","",B6) -> L1 | C16: TECHO | D16: Simplemente apoyada | E16: =IF($B16="","",E6) -> 3 | F16: =IF($B16="","",I6) -> 15 | G16: =IF($B16="","",IF(C16="TECHO",Cargas!$I$16,Cargas!$I$28)+Datos!$C$17*F16/100) -> 5.89 | H16: =IF($B16="","",IF(C16="TECHO",Cargas!$I$34,Cargas!$I$33)) -> 0 | I16: =IF($B16="","",IF(C16="TECHO",Cargas!$I$32,Cargas!$I$35)) -> 1 | J16: =IF($B16="","",MAX(1.4*G16,1.2*G16+1.6*H16+0.5*I16,1.2*G16+1.6*I16+Cargas!$I$36*H16)) -> 8.668 | K16: =IF($B16="","",IF(D16="Voladizo",0,IF(D16="Simplemente apoyada",J16*E16^2/8,J16*E16^2/11))) -> 9.7515 | L16: =IF($B16="","",IF(D16="Voladizo",J16*E16^2/2,IF(D16="Simplemente apoyada",0,J16*E16^2/9))) -> 0 | M16: =IF($B16="","",IF(D16="Voladizo",J16*E16,IF(D16="Simplemente apoyada",J16*E16/2,1.15*J16*E16/2))) -> 13.002 | N16: =IF($B16="","",IF(D16="Voladizo",J16*E16,IF(D16="Simplemente apoyada",J16*E16/2,0.425*J16*E16))) -> 13.002 | O16: =IF($B16="","",IF(D16="Voladizo",J16*E16,IF(D16="Simplemente apoyada",J16*E16/2,1.15*J16*E16))) -> 13.002
B17: =IF(B7="","",B7) -> L2 | C17: ENTREPISO | D17: Continua 2 tramos | E17: =IF($B17="","",E7) -> 3.2 | F17: =IF($B17="","",I7) -> 14 | G17: =IF($B17="","",IF(C17="TECHO",Cargas!$I$16,Cargas!$I$28)+Datos!$C$17*F17/100) -> 5.82 | H17: =IF($B17="","",IF(C17="TECHO",Cargas!$I$34,Cargas!$I$33)) -> 2 | I17: =IF($B17="","",IF(C17="TECHO",Cargas!$I$32,Cargas!$I$35)) -> 0 | J17: =IF($B17="","",MAX(1.4*G17,1.2*G17+1.6*H17+0.5*I17,1.2*G17+1.6*I17+Cargas!$I$36*H17)) -> 10.184 | K17: =IF($B17="","",IF(D17="Voladizo",0,IF(D17="Simplemente apoyada",J17*E17^2/8,J17*E17^2/11))) -> 9.4803782 | L17: =IF($B17="","",IF(D17="Voladizo",J17*E17^2/2,IF(D17="Simplemente apoyada",0,J17*E17^2/9))) -> 11.587129 | M17: =IF($B17="","",IF(D17="Voladizo",J17*E17,IF(D17="Simplemente apoyada",J17*E17/2,1.15*J17*E17/2))) -> 18.73856 | N17: =IF($B17="","",IF(D17="Voladizo",J17*E17,IF(D17="Simplemente apoyada",J17*E17/2,0.425*J17*E17))) -> 13.85024 | O17: =IF($B17="","",IF(D17="Voladizo",J17*E17,IF(D17="Simplemente apoyada",J17*E17/2,1.15*J17*E17))) -> 37.47712
B18: =IF(B8="","",B8) -> L3 | C18: TECHO | D18: Voladizo | E18: =IF($B18="","",E8) -> 1.2 | F18: =IF($B18="","",I8) -> 12 | G18: =IF($B18="","",IF(C18="TECHO",Cargas!$I$16,Cargas!$I$28)+Datos!$C$17*F18/100) -> 5.14 | H18: =IF($B18="","",IF(C18="TECHO",Cargas!$I$34,Cargas!$I$33)) -> 0 | I18: =IF($B18="","",IF(C18="TECHO",Cargas!$I$32,Cargas!$I$35)) -> 1 | J18: =IF($B18="","",MAX(1.4*G18,1.2*G18+1.6*H18+0.5*I18,1.2*G18+1.6*I18+Cargas!$I$36*H18)) -> 7.768 | K18: =IF($B18="","",IF(D18="Voladizo",0,IF(D18="Simplemente apoyada",J18*E18^2/8,J18*E18^2/11))) -> 0 | L18: =IF($B18="","",IF(D18="Voladizo",J18*E18^2/2,IF(D18="Simplemente apoyada",0,J18*E18^2/9))) -> 5.59296 | M18: =IF($B18="","",IF(D18="Voladizo",J18*E18,IF(D18="Simplemente apoyada",J18*E18/2,1.15*J18*E18/2))) -> 9.3216 | N18: =IF($B18="","",IF(D18="Voladizo",J18*E18,IF(D18="Simplemente apoyada",J18*E18/2,0.425*J18*E18))) -> 9.3216 | O18: =IF($B18="","",IF(D18="Voladizo",J18*E18,IF(D18="Simplemente apoyada",J18*E18/2,1.15*J18*E18))) -> 9.3216
B19: =IF(B9="","",B9) | E19: =IF($B19="","",E9) | F19: =IF($B19="","",I9) | G19: =IF($B19="","",IF(C19="TECHO",Cargas!$I$16,Cargas!$I$28)+Datos!$C$17*F19/100) | H19: =IF($B19="","",IF(C19="TECHO",Cargas!$I$34,Cargas!$I$33)) | I19: =IF($B19="","",IF(C19="TECHO",Cargas!$I$32,Cargas!$I$35)) | J19: =IF($B19="","",MAX(1.4*G19,1.2*G19+1.6*H19+0.5*I19,1.2*G19+1.6*I19+Cargas!$I$36*H19)) | K19: =IF($B19="","",IF(D19="Voladizo",0,IF(D19="Simplemente apoyada",J19*E19^2/8,J19*E19^2/11))) | L19: =IF($B19="","",IF(D19="Voladizo",J19*E19^2/2,IF(D19="Simplemente apoyada",0,J19*E19^2/9))) | M19: =IF($B19="","",IF(D19="Voladizo",J19*E19,IF(D19="Simplemente apoyada",J19*E19/2,1.15*J19*E19/2))) | N19: =IF($B19="","",IF(D19="Voladizo",J19*E19,IF(D19="Simplemente apoyada",J19*E19/2,0.425*J19*E19))) | O19: =IF($B19="","",IF(D19="Voladizo",J19*E19,IF(D19="Simplemente apoyada",J19*E19/2,1.15*J19*E19)))
B20: =IF(B10="","",B10) | E20: =IF($B20="","",E10) | F20: =IF($B20="","",I10) | G20: =IF($B20="","",IF(C20="TECHO",Cargas!$I$16,Cargas!$I$28)+Datos!$C$17*F20/100) | H20: =IF($B20="","",IF(C20="TECHO",Cargas!$I$34,Cargas!$I$33)) | I20: =IF($B20="","",IF(C20="TECHO",Cargas!$I$32,Cargas!$I$35)) | J20: =IF($B20="","",MAX(1.4*G20,1.2*G20+1.6*H20+0.5*I20,1.2*G20+1.6*I20+Cargas!$I$36*H20)) | K20: =IF($B20="","",IF(D20="Voladizo",0,IF(D20="Simplemente apoyada",J20*E20^2/8,J20*E20^2/11))) | L20: =IF($B20="","",IF(D20="Voladizo",J20*E20^2/2,IF(D20="Simplemente apoyada",0,J20*E20^2/9))) | M20: =IF($B20="","",IF(D20="Voladizo",J20*E20,IF(D20="Simplemente apoyada",J20*E20/2,1.15*J20*E20/2))) | N20: =IF($B20="","",IF(D20="Voladizo",J20*E20,IF(D20="Simplemente apoyada",J20*E20/2,0.425*J20*E20))) | O20: =IF($B20="","",IF(D20="Voladizo",J20*E20,IF(D20="Simplemente apoyada",J20*E20/2,1.15*J20*E20)))
B21: =IF(B11="","",B11) | E21: =IF($B21="","",E11) | F21: =IF($B21="","",I11) | G21: =IF($B21="","",IF(C21="TECHO",Cargas!$I$16,Cargas!$I$28)+Datos!$C$17*F21/100) | H21: =IF($B21="","",IF(C21="TECHO",Cargas!$I$34,Cargas!$I$33)) | I21: =IF($B21="","",IF(C21="TECHO",Cargas!$I$32,Cargas!$I$35)) | J21: =IF($B21="","",MAX(1.4*G21,1.2*G21+1.6*H21+0.5*I21,1.2*G21+1.6*I21+Cargas!$I$36*H21)) | K21: =IF($B21="","",IF(D21="Voladizo",0,IF(D21="Simplemente apoyada",J21*E21^2/8,J21*E21^2/11))) | L21: =IF($B21="","",IF(D21="Voladizo",J21*E21^2/2,IF(D21="Simplemente apoyada",0,J21*E21^2/9))) | M21: =IF($B21="","",IF(D21="Voladizo",J21*E21,IF(D21="Simplemente apoyada",J21*E21/2,1.15*J21*E21/2))) | N21: =IF($B21="","",IF(D21="Voladizo",J21*E21,IF(D21="Simplemente apoyada",J21*E21/2,0.425*J21*E21))) | O21: =IF($B21="","",IF(D21="Voladizo",J21*E21,IF(D21="Simplemente apoyada",J21*E21/2,1.15*J21*E21)))
B22: qu = máx(1,4·D'; 1,2·D'+1,6·L+0,5·Lr; 1,2·D'+1,6·Lr+fL·L) – CIRSOC 201 §9.2 – con D' = D de Cargas + peso propio γH°A°·h. Voladizo: Mu(−) = qu·L²/2 y Vu = qu·L; la armadura principal va arriba (tabla 3B). Continua 2 tramos: tramos iguales, apoyo extremo simple; Mu(+) = qu·L²/11, Mu(−) = qu·L²/9 y Vu = 1,15·qu·L/2 (CIRSOC 201 §8.3.3). Las reacciones se usan como carga mayorada sobre las vigas de apoyo (en el apoyo central suman los dos tramos).
B24: 3A. Armadura principal de TRAMO (positiva) – flexión CIRSOC 201 cap. 10
B25: Losa | C25: d [cm] | D25: Mu [kNm/m] | E25: Rn [MPa] | F25: ρ req. | G25: As req. [cm²/m] | H25: As mín. [cm²/m] | I25: φ barra [mm] | J25: Separación [cm] | K25: As adopt. [cm²/m] | L25: φMn [kNm/m] | M25: Sep. máx. [cm] | N25: Verificación
B26: =IF(B16="","",B16) -> L1 | C26: =IF($B26="","",F16-Datos!$C$20/10-I26/20) -> 12.5 | D26: =IF($B26="","",K16) -> 9.7515 | E26: =IF($B26="","",IF(D26=0,0,D26*10^6/(0.9*1000*(C26*10)^2))) -> 0.69344 | F26: =IF($B26="","",IF(1-2*E26/(0.85*Datos!$C$14)<0,"AUMENTAR h",0.85*Datos!$C$14/Datos!$C$25*(1-SQRT(1-2*E26/(0.85*Datos!$C$14))))) -> 0.0016789032 | G26: =IF($B26="","",IF(ISNUMBER(F26),F26*1000*C26*10/100,"AUMENTAR h")) -> 2.098629 | H26: =IF($B26="","",IF(Datos!$C$25<=350,0.002,MAX(0.0014,0.0018*420/Datos!$C$25))*1000*F16*10/100) -> 2.7 | I26: 10 | J26: 15 | K26: =IF($B26="","",IF(OR(I26="",J26=""),"",PI()*I26^2/4/J26)) -> 5.2359878 | L26: =IF($B26="","",IF(K26="","",0.9*K26*100*Datos!$C$25*(C26*10-K26*100*Datos!$C$25/(0.85*Datos!$C$14*1000)/2)/10^6)) -> 23.715926 | M26: =IF($B26="","",MIN(3*F16,45)) -> 45 | N26: =IF($B26="","",IF(D26=0,"–",IF(NOT(ISNUMBER(G26)),"AUMENTAR h",IF(K26="","REVISAR",IF(AND(K26>=G26,K26>=H26,L26>=D26,J26<=M26),"CUMPLE","NO CUMPLE"))))) -> CUMPLE
B27: =IF(B17="","",B17) -> L2 | C27: =IF($B27="","",F17-Datos!$C$20/10-I27/20) -> 11.5 | D27: =IF($B27="","",K17) -> 9.4803782 | E27: =IF($B27="","",IF(D27=0,0,D27*10^6/(0.9*1000*(C27*10)^2))) -> 0.7965031 | F27: =IF($B27="","",IF(1-2*E27/(0.85*Datos!$C$14)<0,"AUMENTAR h",0.85*Datos!$C$14/Datos!$C$25*(1-SQRT(1-2*E27/(0.85*Datos!$C$14))))) -> 0.0019333756 | G27: =IF($B27="","",IF(ISNUMBER(F27),F27*1000*C27*10/100,"AUMENTAR h")) -> 2.223382 | H27: =IF($B27="","",IF(Datos!$C$25<=350,0.002,MAX(0.0014,0.0018*420/Datos!$C$25))*1000*F17*10/100) -> 2.52 | I27: 10 | J27: 15 | K27: =IF($B27="","",IF(OR(I27="",J27=""),"",PI()*I27^2/4/J27)) -> 5.2359878 | L27: =IF($B27="","",IF(K27="","",0.9*K27*100*Datos!$C$25*(C27*10-K27*100*Datos!$C$25/(0.85*Datos!$C$14*1000)/2)/10^6)) -> 21.736722 | M27: =IF($B27="","",MIN(3*F17,45)) -> 42 | N27: =IF($B27="","",IF(D27=0,"–",IF(NOT(ISNUMBER(G27)),"AUMENTAR h",IF(K27="","REVISAR",IF(AND(K27>=G27,K27>=H27,L27>=D27,J27<=M27),"CUMPLE","NO CUMPLE"))))) -> CUMPLE
B28: =IF(B18="","",B18) -> L3 | C28: =IF($B28="","",F18-Datos!$C$20/10-I28/20) -> 10 | D28: =IF($B28="","",K18) -> 0 | E28: =IF($B28="","",IF(D28=0,0,D28*10^6/(0.9*1000*(C28*10)^2))) -> 0 | F28: =IF($B28="","",IF(1-2*E28/(0.85*Datos!$C$14)<0,"AUMENTAR h",0.85*Datos!$C$14/Datos!$C$25*(1-SQRT(1-2*E28/(0.85*Datos!$C$14))))) -> 0 | G28: =IF($B28="","",IF(ISNUMBER(F28),F28*1000*C28*10/100,"AUMENTAR h")) -> 0 | H28: =IF($B28="","",IF(Datos!$C$25<=350,0.002,MAX(0.0014,0.0018*420/Datos!$C$25))*1000*F18*10/100) -> 2.16 | K28: =IF($B28="","",IF(OR(I28="",J28=""),"",PI()*I28^2/4/J28)) | L28: =IF($B28="","",IF(K28="","",0.9*K28*100*Datos!$C$25*(C28*10-K28*100*Datos!$C$25/(0.85*Datos!$C$14*1000)/2)/10^6)) | M28: =IF($B28="","",MIN(3*F18,45)) -> 36 | N28: =IF($B28="","",IF(D28=0,"–",IF(NOT(ISNUMBER(G28)),"AUMENTAR h",IF(K28="","REVISAR",IF(AND(K28>=G28,K28>=H28,L28>=D28,J28<=M28),"CUMPLE","NO CUMPLE"))))) -> –
B29: =IF(B19="","",B19) | C29: =IF($B29="","",F19-Datos!$C$20/10-I29/20) | D29: =IF($B29="","",K19) | E29: =IF($B29="","",IF(D29=0,0,D29*10^6/(0.9*1000*(C29*10)^2))) | F29: =IF($B29="","",IF(1-2*E29/(0.85*Datos!$C$14)<0,"AUMENTAR h",0.85*Datos!$C$14/Datos!$C$25*(1-SQRT(1-2*E29/(0.85*Datos!$C$14))))) | G29: =IF($B29="","",IF(ISNUMBER(F29),F29*1000*C29*10/100,"AUMENTAR h")) | H29: =IF($B29="","",IF(Datos!$C$25<=350,0.002,MAX(0.0014,0.0018*420/Datos!$C$25))*1000*F19*10/100) | K29: =IF($B29="","",IF(OR(I29="",J29=""),"",PI()*I29^2/4/J29)) | L29: =IF($B29="","",IF(K29="","",0.9*K29*100*Datos!$C$25*(C29*10-K29*100*Datos!$C$25/(0.85*Datos!$C$14*1000)/2)/10^6)) | M29: =IF($B29="","",MIN(3*F19,45)) | N29: =IF($B29="","",IF(D29=0,"–",IF(NOT(ISNUMBER(G29)),"AUMENTAR h",IF(K29="","REVISAR",IF(AND(K29>=G29,K29>=H29,L29>=D29,J29<=M29),"CUMPLE","NO CUMPLE")))))
B30: =IF(B20="","",B20) | C30: =IF($B30="","",F20-Datos!$C$20/10-I30/20) | D30: =IF($B30="","",K20) | E30: =IF($B30="","",IF(D30=0,0,D30*10^6/(0.9*1000*(C30*10)^2))) | F30: =IF($B30="","",IF(1-2*E30/(0.85*Datos!$C$14)<0,"AUMENTAR h",0.85*Datos!$C$14/Datos!$C$25*(1-SQRT(1-2*E30/(0.85*Datos!$C$14))))) | G30: =IF($B30="","",IF(ISNUMBER(F30),F30*1000*C30*10/100,"AUMENTAR h")) | H30: =IF($B30="","",IF(Datos!$C$25<=350,0.002,MAX(0.0014,0.0018*420/Datos!$C$25))*1000*F20*10/100) | K30: =IF($B30="","",IF(OR(I30="",J30=""),"",PI()*I30^2/4/J30)) | L30: =IF($B30="","",IF(K30="","",0.9*K30*100*Datos!$C$25*(C30*10-K30*100*Datos!$C$25/(0.85*Datos!$C$14*1000)/2)/10^6)) | M30: =IF($B30="","",MIN(3*F20,45)) | N30: =IF($B30="","",IF(D30=0,"–",IF(NOT(ISNUMBER(G30)),"AUMENTAR h",IF(K30="","REVISAR",IF(AND(K30>=G30,K30>=H30,L30>=D30,J30<=M30),"CUMPLE","NO CUMPLE")))))
B31: =IF(B21="","",B21) | C31: =IF($B31="","",F21-Datos!$C$20/10-I31/20) | D31: =IF($B31="","",K21) | E31: =IF($B31="","",IF(D31=0,0,D31*10^6/(0.9*1000*(C31*10)^2))) | F31: =IF($B31="","",IF(1-2*E31/(0.85*Datos!$C$14)<0,"AUMENTAR h",0.85*Datos!$C$14/Datos!$C$25*(1-SQRT(1-2*E31/(0.85*Datos!$C$14))))) | G31: =IF($B31="","",IF(ISNUMBER(F31),F31*1000*C31*10/100,"AUMENTAR h")) | H31: =IF($B31="","",IF(Datos!$C$25<=350,0.002,MAX(0.0014,0.0018*420/Datos!$C$25))*1000*F21*10/100) | K31: =IF($B31="","",IF(OR(I31="",J31=""),"",PI()*I31^2/4/J31)) | L31: =IF($B31="","",IF(K31="","",0.9*K31*100*Datos!$C$25*(C31*10-K31*100*Datos!$C$25/(0.85*Datos!$C$14*1000)/2)/10^6)) | M31: =IF($B31="","",MIN(3*F21,45)) | N31: =IF($B31="","",IF(D31=0,"–",IF(NOT(ISNUMBER(G31)),"AUMENTAR h",IF(K31="","REVISAR",IF(AND(K31>=G31,K31>=H31,L31>=D31,J31<=M31),"CUMPLE","NO CUMPLE")))))
B32: As req. por ρ = 0,85·f'c/fy·(1 − √(1 − 2Rn/(0,85·f'c))), φ = 0,9 (sección controlada por tracción; si no, el programa avisa 'AUMENTAR h'). As mín. = retracción y temperatura (CIRSOC 201 §7.12 y §10.5.4). Separación máxima = menor de 3h y 450 mm.
B34: 3B. Armadura de APOYO (negativa) – solo losas continuas o en voladizo
B35: Losa | C35: d [cm] | D35: Mu [kNm/m] | E35: Rn [MPa] | F35: ρ req. | G35: As req. [cm²/m] | H35: As mín. [cm²/m] | I35: φ barra [mm] | J35: Separación [cm] | K35: As adopt. [cm²/m] | L35: φMn [kNm/m] | M35: Sep. máx. [cm] | N35: Verificación
B36: =IF(B16="","",B16) -> L1 | C36: =IF($B36="","",F16-Datos!$C$20/10-I36/20) -> 13 | D36: =IF($B36="","",L16) -> 0 | E36: =IF($B36="","",IF(D36=0,0,D36*10^6/(0.9*1000*(C36*10)^2))) -> 0 | F36: =IF($B36="","",IF(1-2*E36/(0.85*Datos!$C$14)<0,"AUMENTAR h",0.85*Datos!$C$14/Datos!$C$25*(1-SQRT(1-2*E36/(0.85*Datos!$C$14))))) -> 0 | G36: =IF($B36="","",IF(ISNUMBER(F36),F36*1000*C36*10/100,"AUMENTAR h")) -> 0 | H36: =IF($B36="","",IF(Datos!$C$25<=350,0.002,MAX(0.0014,0.0018*420/Datos!$C$25))*1000*F16*10/100) -> 2.7 | K36: =IF($B36="","",IF(OR(I36="",J36=""),"",PI()*I36^2/4/J36)) | L36: =IF($B36="","",IF(K36="","",0.9*K36*100*Datos!$C$25*(C36*10-K36*100*Datos!$C$25/(0.85*Datos!$C$14*1000)/2)/10^6)) | M36: =IF($B36="","",MIN(3*F16,45)) -> 45 | N36: =IF($B36="","",IF(D36=0,"–",IF(NOT(ISNUMBER(G36)),"AUMENTAR h",IF(K36="","REVISAR",IF(AND(K36>=G36,K36>=H36,L36>=D36,J36<=M36),"CUMPLE","NO CUMPLE"))))) -> –
B37: =IF(B17="","",B17) -> L2 | C37: =IF($B37="","",F17-Datos!$C$20/10-I37/20) -> 11.5 | D37: =IF($B37="","",L17) -> 11.587129 | E37: =IF($B37="","",IF(D37=0,0,D37*10^6/(0.9*1000*(C37*10)^2))) -> 0.97350379 | F37: =IF($B37="","",IF(1-2*E37/(0.85*Datos!$C$14)<0,"AUMENTAR h",0.85*Datos!$C$14/Datos!$C$25*(1-SQRT(1-2*E37/(0.85*Datos!$C$14))))) -> 0.0023735403 | G37: =IF($B37="","",IF(ISNUMBER(F37),F37*1000*C37*10/100,"AUMENTAR h")) -> 2.7295714 | H37: =IF($B37="","",IF(Datos!$C$25<=350,0.002,MAX(0.0014,0.0018*420/Datos!$C$25))*1000*F17*10/100) -> 2.52 | I37: 10 | J37: 15 | K37: =IF($B37="","",IF(OR(I37="",J37=""),"",PI()*I37^2/4/J37)) -> 5.2359878 | L37: =IF($B37="","",IF(K37="","",0.9*K37*100*Datos!$C$25*(C37*10-K37*100*Datos!$C$25/(0.85*Datos!$C$14*1000)/2)/10^6)) -> 21.736722 | M37: =IF($B37="","",MIN(3*F17,45)) -> 42 | N37: =IF($B37="","",IF(D37=0,"–",IF(NOT(ISNUMBER(G37)),"AUMENTAR h",IF(K37="","REVISAR",IF(AND(K37>=G37,K37>=H37,L37>=D37,J37<=M37),"CUMPLE","NO CUMPLE"))))) -> CUMPLE
B38: =IF(B18="","",B18) -> L3 | C38: =IF($B38="","",F18-Datos!$C$20/10-I38/20) -> 9.5 | D38: =IF($B38="","",L18) -> 5.59296 | E38: =IF($B38="","",IF(D38=0,0,D38*10^6/(0.9*1000*(C38*10)^2))) -> 0.68857618 | F38: =IF($B38="","",IF(1-2*E38/(0.85*Datos!$C$14)<0,"AUMENTAR h",0.85*Datos!$C$14/Datos!$C$25*(1-SQRT(1-2*E38/(0.85*Datos!$C$14))))) -> 0.0016669266 | G38: =IF($B38="","",IF(ISNUMBER(F38),F38*1000*C38*10/100,"AUMENTAR h")) -> 1.5835803 | H38: =IF($B38="","",IF(Datos!$C$25<=350,0.002,MAX(0.0014,0.0018*420/Datos!$C$25))*1000*F18*10/100) -> 2.16 | I38: 10 | J38: 15 | K38: =IF($B38="","",IF(OR(I38="",J38=""),"",PI()*I38^2/4/J38)) -> 5.2359878 | L38: =IF($B38="","",IF(K38="","",0.9*K38*100*Datos!$C$25*(C38*10-K38*100*Datos!$C$25/(0.85*Datos!$C$14*1000)/2)/10^6)) -> 17.778315 | M38: =IF($B38="","",MIN(3*F18,45)) -> 36 | N38: =IF($B38="","",IF(D38=0,"–",IF(NOT(ISNUMBER(G38)),"AUMENTAR h",IF(K38="","REVISAR",IF(AND(K38>=G38,K38>=H38,L38>=D38,J38<=M38),"CUMPLE","NO CUMPLE"))))) -> CUMPLE
B39: =IF(B19="","",B19) | C39: =IF($B39="","",F19-Datos!$C$20/10-I39/20) | D39: =IF($B39="","",L19) | E39: =IF($B39="","",IF(D39=0,0,D39*10^6/(0.9*1000*(C39*10)^2))) | F39: =IF($B39="","",IF(1-2*E39/(0.85*Datos!$C$14)<0,"AUMENTAR h",0.85*Datos!$C$14/Datos!$C$25*(1-SQRT(1-2*E39/(0.85*Datos!$C$14))))) | G39: =IF($B39="","",IF(ISNUMBER(F39),F39*1000*C39*10/100,"AUMENTAR h")) | H39: =IF($B39="","",IF(Datos!$C$25<=350,0.002,MAX(0.0014,0.0018*420/Datos!$C$25))*1000*F19*10/100) | K39: =IF($B39="","",IF(OR(I39="",J39=""),"",PI()*I39^2/4/J39)) | L39: =IF($B39="","",IF(K39="","",0.9*K39*100*Datos!$C$25*(C39*10-K39*100*Datos!$C$25/(0.85*Datos!$C$14*1000)/2)/10^6)) | M39: =IF($B39="","",MIN(3*F19,45)) | N39: =IF($B39="","",IF(D39=0,"–",IF(NOT(ISNUMBER(G39)),"AUMENTAR h",IF(K39="","REVISAR",IF(AND(K39>=G39,K39>=H39,L39>=D39,J39<=M39),"CUMPLE","NO CUMPLE")))))
B40: =IF(B20="","",B20) | C40: =IF($B40="","",F20-Datos!$C$20/10-I40/20) | D40: =IF($B40="","",L20) | E40: =IF($B40="","",IF(D40=0,0,D40*10^6/(0.9*1000*(C40*10)^2))) | F40: =IF($B40="","",IF(1-2*E40/(0.85*Datos!$C$14)<0,"AUMENTAR h",0.85*Datos!$C$14/Datos!$C$25*(1-SQRT(1-2*E40/(0.85*Datos!$C$14))))) | G40: =IF($B40="","",IF(ISNUMBER(F40),F40*1000*C40*10/100,"AUMENTAR h")) | H40: =IF($B40="","",IF(Datos!$C$25<=350,0.002,MAX(0.0014,0.0018*420/Datos!$C$25))*1000*F20*10/100) | K40: =IF($B40="","",IF(OR(I40="",J40=""),"",PI()*I40^2/4/J40)) | L40: =IF($B40="","",IF(K40="","",0.9*K40*100*Datos!$C$25*(C40*10-K40*100*Datos!$C$25/(0.85*Datos!$C$14*1000)/2)/10^6)) | M40: =IF($B40="","",MIN(3*F20,45)) | N40: =IF($B40="","",IF(D40=0,"–",IF(NOT(ISNUMBER(G40)),"AUMENTAR h",IF(K40="","REVISAR",IF(AND(K40>=G40,K40>=H40,L40>=D40,J40<=M40),"CUMPLE","NO CUMPLE")))))
B41: =IF(B21="","",B21) | C41: =IF($B41="","",F21-Datos!$C$20/10-I41/20) | D41: =IF($B41="","",L21) | E41: =IF($B41="","",IF(D41=0,0,D41*10^6/(0.9*1000*(C41*10)^2))) | F41: =IF($B41="","",IF(1-2*E41/(0.85*Datos!$C$14)<0,"AUMENTAR h",0.85*Datos!$C$14/Datos!$C$25*(1-SQRT(1-2*E41/(0.85*Datos!$C$14))))) | G41: =IF($B41="","",IF(ISNUMBER(F41),F41*1000*C41*10/100,"AUMENTAR h")) | H41: =IF($B41="","",IF(Datos!$C$25<=350,0.002,MAX(0.0014,0.0018*420/Datos!$C$25))*1000*F21*10/100) | K41: =IF($B41="","",IF(OR(I41="",J41=""),"",PI()*I41^2/4/J41)) | L41: =IF($B41="","",IF(K41="","",0.9*K41*100*Datos!$C$25*(C41*10-K41*100*Datos!$C$25/(0.85*Datos!$C$14*1000)/2)/10^6)) | M41: =IF($B41="","",MIN(3*F21,45)) | N41: =IF($B41="","",IF(D41=0,"–",IF(NOT(ISNUMBER(G41)),"AUMENTAR h",IF(K41="","REVISAR",IF(AND(K41>=G41,K41>=H41,L41>=D41,J41<=M41),"CUMPLE","NO CUMPLE")))))
B43: 3C. Corte y armadura de reparto (retracción y temperatura)
B44: Losa | C44: Vu [kN/m] | D44: d [cm] | E44: φVc [kN/m] | F44: Corte | G44: φ reparto [mm] | H44: Sep. reparto [cm] | I44: As reparto [cm²/m] | J44: As mín. [cm²/m] | K44: Sep. máx. [cm] | L44: Reparto
B45: =IF(B16="","",B16) -> L1 | C45: =IF($B45="","",M16) -> 13.002 | D45: =IF($B45="","",IF(D16="Voladizo",C36,C26)) -> 12.5 | E45: =IF($B45="","",0.75*SQRT(Datos!$C$14)/6*D45*10) -> 78.125 | F45: =IF($B45="","",IF(C45<=E45,"CUMPLE","NO CUMPLE")) -> CUMPLE | G45: 8 | H45: 15 | I45: =IF($B45="","",IF(OR(G45="",H45=""),"",PI()*G45^2/4/H45)) -> 3.3510322 | J45: =IF($B45="","",IF(Datos!$C$25<=350,0.002,MAX(0.0014,0.0018*420/Datos!$C$25))*1000*F16*10/100) -> 2.7 | K45: =IF($B45="","",MIN(5*F16,45)) -> 45 | L45: =IF($B45="","",IF(I45="","REVISAR",IF(AND(I45>=J45,H45<=K45),"CUMPLE","NO CUMPLE"))) -> CUMPLE
...

Sheet Viguetas y Correas
A1: VIGUETAS PRETENSADAS Y CORREAS DE MADERA
A2: Sistemas livianos de entrepiso y cubierta. Verificación de flexión, corte y flecha con cargas de servicio (las cargas D, L y Lr se toman de la hoja Cargas).
B4: 1. Viguetas pretensadas (sistema vigueta + bovedilla + capa de compresión)
B5: Cargas a utilizar en la verificación: | E5: Servicio | G5: Confirmar en el catálogo del fabricante si M adm es momento de servicio o último (la planilla original lo mezclaba).
B6: Vigueta | C6: Nivel | D6: Serie | E6: Luz L [m] | F6: Separación entre ejes [m] | G6: Peso propio del sistema [kN/m²] | H6: q de cálculo [kN/m²] | I6: q lineal [kN/m] | J6: M [kNm] | K6: V [kN] | L6: M adm [kNm] | M6: Verificación
B7: VP1 | C7: ENTREPISO | D7: Serie 3a | E7: 4 | F7: 0.7 | G7: 2.5 | H7: =IF($B7="","",IF($E$5="Servicio",IF(C7="TECHO",Cargas!$I$16,Cargas!$I$28)+G7+IF(C7="TECHO",Cargas!$I$34,Cargas!$I$33)+IF(C7="TECHO",Cargas!$I$32,Cargas!$I$35),MAX(1.4*(IF(C7="TECHO",Cargas!$I$16,Cargas!$I$28)+G7),1.2*(IF(C7="TECHO",Cargas!$I$16,Cargas!$I$28)+G7)+1.6*IF(C7="TECHO",Cargas!$I$34,Cargas!$I$33)+0.5*IF(C7="TECHO",Cargas!$I$32,Cargas!$I$35),1.2*(IF(C7="TECHO",Cargas!$I$16,Cargas!$I$28)+G7)+1.6*IF(C7="TECHO",Cargas!$I$32,Cargas!$I$35)+Cargas!$I$36*IF(C7="TECHO",Cargas!$I$34,Cargas!$I$33)))) -> 6.82 | I7: =IF($B7="","",H7*F7) -> 4.774 | J7: =IF($B7="","",I7*E7^2/8) -> 9.548 | K7: =IF($B7="","",I7*E7/2) -> 9.548 | L7: =IF($B7="","",INDEX(Tablas!$L$62:$L$71,MATCH(D7,Tablas!$K$62:$K$71,0))) -> 11.92 | M7: =IF($B7="","",IF(J7<=L7,"CUMPLE","NO CUMPLE")) -> CUMPLE
B8: VP2 | C8: TECHO | D8: Serie 2a | E8: 3.5 | F8: 0.7 | G8: 2.5 | H8: =IF($B8="","",IF($E$5="Servicio",IF(C8="TECHO",Cargas!$I$16,Cargas!$I$28)+G8+IF(C8="TECHO",Cargas!$I$34,Cargas!$I$33)+IF(C8="TECHO",Cargas!$I$32,Cargas!$I$35),MAX(1.4*(IF(C8="TECHO",Cargas!$I$16,Cargas!$I$28)+G8),1.2*(IF(C8="TECHO",Cargas!$I$16,Cargas!$I$28)+G8)+1.6*IF(C8="TECHO",Cargas!$I$34,Cargas!$I$33)+0.5*IF(C8="TECHO",Cargas!$I$32,Cargas!$I$35),1.2*(IF(C8="TECHO",Cargas!$I$16,Cargas!$I$28)+G8)+1.6*IF(C8="TECHO",Cargas!$I$32,Cargas!$I$35)+Cargas!$I$36*IF(C8="TECHO",Cargas!$I$34,Cargas!$I$33)))) -> 5.64 | I8: =IF($B8="","",H8*F8) -> 3.948 | J8: =IF($B8="","",I8*E8^2/8) -> 6.045375 | K8: =IF($B8="","",I8*E8/2) -> 6.909 | L8: =IF($B8="","",INDEX(Tablas!$L$62:$L$71,MATCH(D8,Tablas!$K$62:$K$71,0))) -> 10.89 | M8: =IF($B8="","",IF(J8<=L8,"CUMPLE","NO CUMPLE")) -> CUMPLE
H9: =IF($B9="","",IF($E$5="Servicio",IF(C9="TECHO",Cargas!$I$16,Cargas!$I$28)+G9+IF(C9="TECHO",Cargas!$I$34,Cargas!$I$33)+IF(C9="TECHO",Cargas!$I$32,Cargas!$I$35),MAX(1.4*(IF(C9="TECHO",Cargas!$I$16,Cargas!$I$28)+G9),1.2*(IF(C9="TECHO",Cargas!$I$16,Cargas!$I$28)+G9)+1.6*IF(C9="TECHO",Cargas!$I$34,Cargas!$I$33)+0.5*IF(C9="TECHO",Cargas!$I$32,Cargas!$I$35),1.2*(IF(C9="TECHO",Cargas!$I$16,Cargas!$I$28)+G9)+1.6*IF(C9="TECHO",Cargas!$I$32,Cargas!$I$35)+Cargas!$I$36*IF(C9="TECHO",Cargas!$I$34,Cargas!$I$33)))) | I9: =IF($B9="","",H9*F9) | J9: =IF($B9="","",I9*E9^2/8) | K9: =IF($B9="","",I9*E9/2) | L9: =IF($B9="","",INDEX(Tablas!$L$62:$L$71,MATCH(D9,Tablas!$K$62:$K$71,0))) | M9: =IF($B9="","",IF(J9<=L9,"CUMPLE","NO CUMPLE"))
H10: =IF($B10="","",IF($E$5="Servicio",IF(C10="TECHO",Cargas!$I$16,Cargas!$I$28)+G10+IF(C10="TECHO",Cargas!$I$34,Cargas!$I$33)+IF(C10="TECHO",Cargas!$I$32,Cargas!$I$35),MAX(1.4*(IF(C10="TECHO",Cargas!$I$16,Cargas!$I$28)+G10),1.2*(IF(C10="TECHO",Cargas!$I$16,Cargas!$I$28)+G10)+1.6*IF(C10="TECHO",Cargas!$I$34,Cargas!$I$33)+0.5*IF(C10="TECHO",Cargas!$I$32,Cargas!$I$35),1.2*(IF(C10="TECHO",Cargas!$I$16,Cargas!$I$28)+G10)+1.6*IF(C10="TECHO",Cargas!$I$32,Cargas!$I$35)+Cargas!$I$36*IF(C10="TECHO",Cargas!$I$34,Cargas!$I$33)))) | I10: =IF($B10="","",H10*F10) | J10: =IF($B10="","",I10*E10^2/8) | K10: =IF($B10="","",I10*E10/2) | L10: =IF($B10="","",INDEX(Tablas!$L$62:$L$71,MATCH(D10,Tablas!$K$62:$K$71,0))) | M10: =IF($B10="","",IF(J10<=L10,"CUMPLE","NO CUMPLE"))
B11: Corrección respecto de la planilla original: el momento admisible se leía como 5,61 + valor de la serie (se sumaba siempre 5,61 kNm); ahora se toma directamente el valor de la serie. El peso propio del sistema (vigueta + bovedilla + capa) es dato del fabricante: 2,5 kN/m² es un valor de ejemplo. Verificar además la flecha y los apoyos con el catálogo.
B13: 2. Correas de madera (verificación por tensiones admisibles, cargas de servicio)
B14: Correa | C14: Nivel | D14: Sección (pino laminado) | E14: b [m] | F14: h [m] | G14: Luz L [m] | H14: Separación [m] | I14: Pendiente α [°] | J14: E [MPa] | K14: Fb adm [MPa] | L14: Fv adm [MPa] | M14: q lineal [kN/m] | N14: σ flexión [MPa] | O14: τ corte [MPa] | P14: Flecha [mm] | Q14: Flecha adm. L/x | R14: Verificación
B15: C1 | C15: TECHO | D15: Pino Laminado 4" x 9" (9 x 22,2 cm) | E15: =IF($B15="","",INDEX(Tablas!$S$5:$S$124,MATCH(D15,Tablas!$Q$5:$Q$124,0))) -> 0.09 | F15: =IF($B15="","",INDEX(Tablas!$T$5:$T$124,MATCH(D15,Tablas!$Q$5:$Q$124,0))) -> 0.222 | G15: 3 | H15: 0.6 | I15: 15 | J15: 11200 | K15: 6.3 | L15: 0.7 | M15: =IF($B15="","",(IF(C15="TECHO",Cargas!$I$16,Cargas!$I$28)+IF(C15="TECHO",Cargas!$I$34+Cargas!$I$32,Cargas!$I$33+Cargas!$I$35))*H15+INDEX(Tablas!$R$5:$R$124,MATCH(D15,Tablas!$Q$5:$Q$124,0))) -> 2.00388 | N15: =IF($B15="","",(M15*COS(RADIANS(I15))*G15^2/8)/(E15*F15^2/6)/1000) -> 2.9455799 | O15: =IF($B15="","",1.5*(M15*COS(RADIANS(I15))*G15/2)/(E15*F15)/1000) -> 0.21797291 | P15: =IF($B15="","",5*M15*COS(RADIANS(I15))*G15^4/(384*J15*1000*(E15*F15^3/12))*1000) -> 2.2212686 | Q15: 300 | R15: =IF($B15="","",IF(AND(N15<=K15,O15<=L15,P15<=G15*1000/Q15),"CUMPLE","NO CUMPLE")) -> CUMPLE
E16: =IF($B16="","",INDEX(Tablas!$S$5:$S$124,MATCH(D16,Tablas!$Q$5:$Q$124,0))) | F16: =IF($B16="","",INDEX(Tablas!$T$5:$T$124,MATCH(D16,Tablas!$Q$5:$Q$124,0))) | M16: =IF($B16="","",(IF(C16="TECHO",Cargas!$I$16,Cargas!$I$28)+IF(C16="TECHO",Cargas!$I$34+Cargas!$I$32,Cargas!$I$33+Cargas!$I$35))*H16+INDEX(Tablas!$R$5:$R$124,MATCH(D16,Tablas!$Q$5:$Q$124,0))) | N16: =IF($B16="","",(M16*COS(RADIANS(I16))*G16^2/8)/(E16*F16^2/6)/1000) | O16: =IF($B16="","",1.5*(M16*COS(RADIANS(I16))*G16/2)/(E16*F16)/1000) | P16: =IF($B16="","",5*M16*COS(RADIANS(I16))*G16^4/(384*J16*1000*(E16*F16^3/12))*1000) | R16: =IF($B16="","",IF(AND(N16<=K16,O16<=L16,P16<=G16*1000/Q16),"CUMPLE","NO CUMPLE"))
E17: =IF($B17="","",INDEX(Tablas!$S$5:$S$124,MATCH(D17,Tablas!$Q$5:$Q$124,0))) | F17: =IF($B17="","",INDEX(Tablas!$T$5:$T$124,MATCH(D17,Tablas!$Q$5:$Q$124,0))) | M17: =IF($B17="","",(IF(C17="TECHO",Cargas!$I$16,Cargas!$I$28)+IF(C17="TECHO",Cargas!$I$34+Cargas!$I$32,Cargas!$I$33+Cargas!$I$35))*H17+INDEX(Tablas!$R$5:$R$124,MATCH(D17,Tablas!$Q$5:$Q$124,0))) | N17: =IF($B17="","",(M17*COS(RADIANS(I17))*G17^2/8)/(E17*F17^2/6)/1000) | O17: =IF($B17="","",1.5*(M17*COS(RADIANS(I17))*G17/2)/(E17*F17)/1000) | P17: =IF($B17="","",5*M17*COS(RADIANS(I17))*G17^4/(384*J17*1000*(E17*F17^3/12))*1000) | R17: =IF($B17="","",IF(AND(N17<=K17,O17<=L17,P17<=G17*1000/Q17),"CUMPLE","NO CUMPLE"))
E18: =IF($B18="","",INDEX(Tablas!$S$5:$S$124,MATCH(D18,Tablas!$Q$5:$Q$124,0))) | F18: =IF($B18="","",INDEX(Tablas!$T$5:$T$124,MATCH(D18,Tablas!$Q$5:$Q$124,0))) | M18: =IF($B18="","",(IF(C18="TECHO",Cargas!$I$16,Cargas!$I$28)+IF(C18="TECHO",Cargas!$I$34+Cargas!$I$32,Cargas!$I$33+Cargas!$I$35))*H18+INDEX(Tablas!$R$5:$R$124,MATCH(D18,Tablas!$Q$5:$Q$124,0))) | N18: =IF($B18="","",(M18*COS(RADIANS(I18))*G18^2/8)/(E18*F18^2/6)/1000) | O18: =IF($B18="","",1.5*(M18*COS(RADIANS(I18))*G18/2)/(E18*F18)/1000) | P18: =IF($B18="","",5*M18*COS(RADIANS(I18))*G18^4/(384*J18*1000*(E18*F18^3/12))*1000) | R18: =IF($B18="","",IF(AND(N18<=K18,O18<=L18,P18<=G18*1000/Q18),"CUMPLE","NO CUMPLE"))
B19: Cargas de servicio: q = (D + L + Lr)·separación + peso propio de la correa. Flecha = 5·q·cosα·L⁴/(384·E·I) con E en kN/m² (1 MPa = 1000 kN/m²); la planilla original multiplicaba dos veces por la separación y mezclaba unidades (el resultado era ≈ 50 veces mayor que el real). Los valores admisibles Fb, Fv y E son datos de la clase resistente de la madera (CIRSOC 601): los de ejemplo son los de la planilla original; reemplazar por los del material adoptado. Flecha admisible L/300 en cubiertas, L/200 en entrepisos (valor orientativo).

Sheet Vigas
A1: VIGAS DE HORMIGÓN ARMADO (CIRSOC 201-2005)
A2: Sección rectangular con armadura simple en una capa. Esfuerzos por coeficientes aproximados (CIRSOC 201 §8.3.3). Vigas con torsión, vigas T o análisis de pórtico: verificar aparte.
B4: 1. Predimensionado de altura – CIRSOC 201 Tabla 9.5(a) (vigas)
B5: Viga | C5: Condición de apoyo | D5: Luz L [m] | E5: Divisor (L/x) | F5: Factor fy | G5: h mín [cm] | H5: h adoptado [cm] | I5: Verificación
B6: V1 | C6: Un extremo continuo | D6: 3.5 | E6: =IF($B6="","",INDEX(Tablas!$L$43:$O$44,2,MATCH(C6,Tablas!$L$42:$O$42,0))) -> 18.5 | F6: =IF($B6="","",IF(Datos!$C$25=420,1,0.4+Datos!$C$25/700)) -> 1 | G6: =IF($B6="","",D6/E6*F6*100) -> 18.918919 | H6: 40 | I6: =IF($B6="","",IF(H6>=G6,"CUMPLE","NO CUMPLE")) -> CUMPLE
B7: V2 | C7: Simplemente apoyado | D7: 3 | E7: =IF($B7="","",INDEX(Tablas!$L$43:$O$44,2,MATCH(C7,Tablas!$L$42:$O$42,0))) -> 16 | F7: =IF($B7="","",IF(Datos!$C$25=420,1,0.4+Datos!$C$25/700)) -> 1 | G7: =IF($B7="","",D7/E7*F7*100) -> 18.75 | H7: 40 | I7: =IF($B7="","",IF(H7>=G7,"CUMPLE","NO CUMPLE")) -> CUMPLE
E8: =IF($B8="","",INDEX(Tablas!$L$43:$O$44,2,MATCH(C8,Tablas!$L$42:$O$42,0))) | F8: =IF($B8="","",IF(Datos!$C$25=420,1,0.4+Datos!$C$25/700)) | G8: =IF($B8="","",D8/E8*F8*100) | I8: =IF($B8="","",IF(H8>=G8,"CUMPLE","NO CUMPLE"))
E9: =IF($B9="","",INDEX(Tablas!$L$43:$O$44,2,MATCH(C9,Tablas!$L$42:$O$42,0))) | F9: =IF($B9="","",IF(Datos!$C$25=420,1,0.4+Datos!$C$25/700)) | G9: =IF($B9="","",D9/E9*F9*100) | I9: =IF($B9="","",IF(H9>=G9,"CUMPLE","NO CUMPLE"))
E10: =IF($B10="","",INDEX(Tablas!$L$43:$O$44,2,MATCH(C10,Tablas!$L$42:$O$42,0))) | F10: =IF($B10="","",IF(Datos!$C$25=420,1,0.4+Datos!$C$25/700)) | G10: =IF($B10="","",D10/E10*F10*100) | I10: =IF($B10="","",IF(H10>=G10,"CUMPLE","NO CUMPLE"))
E11: =IF($B11="","",INDEX(Tablas!$L$43:$O$44,2,MATCH(C11,Tablas!$L$42:$O$42,0))) | F11: =IF($B11="","",IF(Datos!$C$25=420,1,0.4+Datos!$C$25/700)) | G11: =IF($B11="","",D11/E11*F11*100) | I11: =IF($B11="","",IF(H11>=G11,"CUMPLE","NO CUMPLE"))
B13: 2. Cargas y esfuerzos
B14: Viga | C14: Esquema estático | D14: bw [cm] | E14: h [cm] | F14: L [m] | G14: Estribo φ [mm] | H14: Reacción de losas mayorada [kN/m] | I14: D adicional (muros, etc.) [kN/m] | J14: L adicional [kN/m] | K14: D viga total [kN/m] | L14: qu [kN/m] | M14: Mu(+) [kNm] | N14: Mu(−) [kNm] | O14: Vu [kN]
B15: =IF(B6="","",B6) -> V1 | C15: Continua 2 tramos – tramo extremo | D15: 20 | E15: =IF($B15="","",H6) -> 40 | F15: =IF($B15="","",D6) -> 3.5 | G15: 8 | H15: =Losas!$O$17 -> 37.47712 | I15: =Cargas!$I$51 -> 5.616 | J15: 0 | K15: =IF($B15="","",Datos!$C$17*D15*E15/10000+N(I15)) -> 7.616 | L15: =IF($B15="","",N(H15)+MAX(1.4*K15,1.2*K15+1.6*N(J15))) -> 48.13952 | M15: =IF($B15="","",INDEX(Tablas!$L$34:$L$38,MATCH(C15,Tablas!$K$34:$K$38,0))*L15*F15^2) -> 53.60992 | N15: =IF($B15="","",INDEX(Tablas!$M$34:$M$38,MATCH(C15,Tablas!$K$34:$K$38,0))*L15*F15^2) -> 65.523236 | O15: =IF($B15="","",INDEX(Tablas!$N$34:$N$38,MATCH(C15,Tablas!$K$34:$K$38,0))*L15*F15) -> 96.880784
B16: =IF(B7="","",B7) -> V2 | C16: Simplemente apoyada | D16: 20 | E16: =IF($B16="","",H7) -> 40 | F16: =IF($B16="","",D7) -> 3 | G16: 8 | H16: =Losas!$N$16 -> 13.002 | I16: 0 | J16: 0 | K16: =IF($B16="","",Datos!$C$17*D16*E16/10000+N(I16)) -> 2 | L16: =IF($B16="","",N(H16)+MAX(1.4*K16,1.2*K16+1.6*N(J16))) -> 15.802 | M16: =IF($B16="","",INDEX(Tablas!$L$34:$L$38,MATCH(C16,Tablas!$K$34:$K$38,0))*L16*F16^2) -> 17.77725 | N16: =IF($B16="","",INDEX(Tablas!$M$34:$M$38,MATCH(C16,Tablas!$K$34:$K$38,0))*L16*F16^2) -> 0 | O16: =IF($B16="","",INDEX(Tablas!$N$34:$N$38,MATCH(C16,Tablas!$K$34:$K$38,0))*L16*F16) -> 23.703
B17: =IF(B8="","",B8) | E17: =IF($B17="","",H8) | F17: =IF($B17="","",D8) | K17: =IF($B17="","",Datos!$C$17*D17*E17/10000+N(I17)) | L17: =IF($B17="","",N(H17)+MAX(1.4*K17,1.2*K17+1.6*N(J17))) | M17: =IF($B17="","",INDEX(Tablas!$L$34:$L$38,MATCH(C17,Tablas!$K$34:$K$38,0))*L17*F17^2) | N17: =IF($B17="","",INDEX(Tablas!$M$34:$M$38,MATCH(C17,Tablas!$K$34:$K$38,0))*L17*F17^2) | O17: =IF($B17="","",INDEX(Tablas!$N$34:$N$38,MATCH(C17,Tablas!$K$34:$K$38,0))*L17*F17)
B18: =IF(B9="","",B9) | E18: =IF($B18="","",H9) | F18: =IF($B18="","",D9) | K18: =IF($B18="","",Datos!$C$17*D18*E18/10000+N(I18)) | L18: =IF($B18="","",N(H18)+MAX(1.4*K18,1.2*K18+1.6*N(J18))) | M18: =IF($B18="","",INDEX(Tablas!$L$34:$L$38,MATCH(C18,Tablas!$K$34:$K$38,0))*L18*F18^2) | N18: =IF($B18="","",INDEX(Tablas!$M$34:$M$38,MATCH(C18,Tablas!$K$34:$K$38,0))*L18*F18^2) | O18: =IF($B18="","",INDEX(Tablas!$N$34:$N$38,MATCH(C18,Tablas!$K$34:$K$38,0))*L18*F18)
B19: =IF(B10="","",B10) | E19: =IF($B19="","",H10) | F19: =IF($B19="","",D10) | K19: =IF($B19="","",Datos!$C$17*D19*E19/10000+N(I19)) | L19: =IF($B19="","",N(H19)+MAX(1.4*K19,1.2*K19+1.6*N(J19))) | M19: =IF($B19="","",INDEX(Tablas!$L$34:$L$38,MATCH(C19,Tablas!$K$34:$K$38,0))*L19*F19^2) | N19: =IF($B19="","",INDEX(Tablas!$M$34:$M$38,MATCH(C19,Tablas!$K$34:$K$38,0))*L19*F19^2) | O19: =IF($B19="","",INDEX(Tablas!$N$34:$N$38,MATCH(C19,Tablas!$K$34:$K$38,0))*L19*F19)
B20: =IF(B11="","",B11) | E20: =IF($B20="","",H11) | F20: =IF($B20="","",D11) | K20: =IF($B20="","",Datos!$C$17*D20*E20/10000+N(I20)) | L20: =IF($B20="","",N(H20)+MAX(1.4*K20,1.2*K20+1.6*N(J20))) | M20: =IF($B20="","",INDEX(Tablas!$L$34:$L$38,MATCH(C20,Tablas!$K$34:$K$38,0))*L20*F20^2) | N20: =IF($B20="","",INDEX(Tablas!$M$34:$M$38,MATCH(C20,Tablas!$K$34:$K$38,0))*L20*F20^2) | O20: =IF($B20="","",INDEX(Tablas!$N$34:$N$38,MATCH(C20,Tablas!$K$34:$K$38,0))*L20*F20)
B21: Las celdas con letra verde (reacciones de losas y mampostería) están vinculadas a las hojas Losas y Cargas; se pueden sobrescribir. qu = reacción de losas (ya mayorada) + máx(1,4·D; 1,2·D + 1,6·L) con D = peso propio de la viga + cargas permanentes adicionales. Mu = coeficiente·qu·L² (tabla de la hoja Tablas).
B23: 3. Armadura longitudinal (flexión) – CIRSOC 201 cap. 10
